{
 "cells": [
  {
   "cell_type": "markdown",
   "metadata": {},
   "source": [
    "# La gestion des erreurs en Python\n",
    "Elements issus de google learn.\n",
    "## Préambule\n",
    "Tout programme peut soulever des erreurs, même les plus éprouvés. La gestion des erreurs permet soit un retour utilisateur/concepteur plus compréhensible, soit une gestion automatisée des erreurs identifiées. En résumé, c'est un moyen de gestion pour que les erreurs n'apparaissent pas ou qu'elles n'affichent que des informations utiles.\n",
    "\n",
    "Une certaine communauté considère que l'utilisation de la gestion d'erreur dans un programme censement fini est la preuve d'une incompétence du programmeur. Faisons en fie.\n",
    "## Présentation d'une erreur\n",
    "Voyons ci-après sous quelle forme se présente une erreur en Python. Nous pouvons par exemple tenter de lire un fichier qui n'existe pas ou qui ne se trouve pas à l'endroit attendu."
   ]
  },
  {
   "cell_type": "code",
   "execution_count": 1,
   "metadata": {},
   "outputs": [
    {
     "ename": "FileNotFoundError",
     "evalue": "[Errno 2] No such file or directory: 'path/to/mars.jpg'",
     "output_type": "error",
     "traceback": [
      "\u001b[1;31m---------------------------------------------------------------------------\u001b[0m",
      "\u001b[1;31mFileNotFoundError\u001b[0m                         Traceback (most recent call last)",
      "Cell \u001b[1;32mIn[1], line 1\u001b[0m\n\u001b[1;32m----> 1\u001b[0m \u001b[38;5;28;43mopen\u001b[39;49m\u001b[43m(\u001b[49m\u001b[38;5;124;43m\"\u001b[39;49m\u001b[38;5;124;43mpath/to/mars.jpg\u001b[39;49m\u001b[38;5;124;43m\"\u001b[39;49m\u001b[43m)\u001b[49m\n",
      "File \u001b[1;32md:\\Programmation\\PYTHON\\hello-world\\env\\Lib\\site-packages\\IPython\\core\\interactiveshell.py:310\u001b[0m, in \u001b[0;36m_modified_open\u001b[1;34m(file, *args, **kwargs)\u001b[0m\n\u001b[0;32m    303\u001b[0m \u001b[38;5;28;01mif\u001b[39;00m file \u001b[38;5;129;01min\u001b[39;00m {\u001b[38;5;241m0\u001b[39m, \u001b[38;5;241m1\u001b[39m, \u001b[38;5;241m2\u001b[39m}:\n\u001b[0;32m    304\u001b[0m     \u001b[38;5;28;01mraise\u001b[39;00m \u001b[38;5;167;01mValueError\u001b[39;00m(\n\u001b[0;32m    305\u001b[0m         \u001b[38;5;124mf\u001b[39m\u001b[38;5;124m\"\u001b[39m\u001b[38;5;124mIPython won\u001b[39m\u001b[38;5;124m'\u001b[39m\u001b[38;5;124mt let you open fd=\u001b[39m\u001b[38;5;132;01m{\u001b[39;00mfile\u001b[38;5;132;01m}\u001b[39;00m\u001b[38;5;124m by default \u001b[39m\u001b[38;5;124m\"\u001b[39m\n\u001b[0;32m    306\u001b[0m         \u001b[38;5;124m\"\u001b[39m\u001b[38;5;124mas it is likely to crash IPython. If you know what you are doing, \u001b[39m\u001b[38;5;124m\"\u001b[39m\n\u001b[0;32m    307\u001b[0m         \u001b[38;5;124m\"\u001b[39m\u001b[38;5;124myou can use builtins\u001b[39m\u001b[38;5;124m'\u001b[39m\u001b[38;5;124m open.\u001b[39m\u001b[38;5;124m\"\u001b[39m\n\u001b[0;32m    308\u001b[0m     )\n\u001b[1;32m--> 310\u001b[0m \u001b[38;5;28;01mreturn\u001b[39;00m \u001b[43mio_open\u001b[49m\u001b[43m(\u001b[49m\u001b[43mfile\u001b[49m\u001b[43m,\u001b[49m\u001b[43m \u001b[49m\u001b[38;5;241;43m*\u001b[39;49m\u001b[43margs\u001b[49m\u001b[43m,\u001b[49m\u001b[43m \u001b[49m\u001b[38;5;241;43m*\u001b[39;49m\u001b[38;5;241;43m*\u001b[39;49m\u001b[43mkwargs\u001b[49m\u001b[43m)\u001b[49m\n",
      "\u001b[1;31mFileNotFoundError\u001b[0m: [Errno 2] No such file or directory: 'path/to/mars.jpg'"
     ]
    }
   ],
   "source": [
    "open(\"path/to/mars.jpg\")"
   ]
  },
  {
   "cell_type": "markdown",
   "metadata": {},
   "source": [
    "Dans le cas présent, le retour est très (trop) complet et déjà partiellement traité par une exception.\n",
    "\n",
    "Nous relevons un `FileNotFoundError` à la ligne 1 de notre programme. Cette erreur est reprise en fin d'avertissement et nous voyons qu'il s'agit de l'erreur n°2 selon laquelle le fichier ou le dossier n'existe pas. Pour l'instant, et peut-être pour le reste de ce notebook, je ne relève pas l'explication de Ipython qui ne nous laisse pas ouvrir le fichier par défaut.\n",
    "\n",
    "Réessayons autre chose."
   ]
  },
  {
   "cell_type": "code",
   "execution_count": 2,
   "metadata": {},
   "outputs": [
    {
     "ename": "FileNotFoundError",
     "evalue": "[Errno 2] No such file or directory: '/path/to/mars.jpg'",
     "output_type": "error",
     "traceback": [
      "\u001b[1;31m---------------------------------------------------------------------------\u001b[0m",
      "\u001b[1;31mFileNotFoundError\u001b[0m                         Traceback (most recent call last)",
      "Cell \u001b[1;32mIn[2], line 5\u001b[0m\n\u001b[0;32m      2\u001b[0m     \u001b[38;5;28mopen\u001b[39m(\u001b[38;5;124m\"\u001b[39m\u001b[38;5;124m/path/to/mars.jpg\u001b[39m\u001b[38;5;124m\"\u001b[39m)\n\u001b[0;32m      4\u001b[0m \u001b[38;5;28;01mif\u001b[39;00m \u001b[38;5;18m__name__\u001b[39m \u001b[38;5;241m==\u001b[39m \u001b[38;5;124m'\u001b[39m\u001b[38;5;124m__main__\u001b[39m\u001b[38;5;124m'\u001b[39m:\n\u001b[1;32m----> 5\u001b[0m     \u001b[43mmain\u001b[49m\u001b[43m(\u001b[49m\u001b[43m)\u001b[49m\n",
      "Cell \u001b[1;32mIn[2], line 2\u001b[0m, in \u001b[0;36mmain\u001b[1;34m()\u001b[0m\n\u001b[0;32m      1\u001b[0m \u001b[38;5;28;01mdef\u001b[39;00m \u001b[38;5;21mmain\u001b[39m():\n\u001b[1;32m----> 2\u001b[0m     \u001b[38;5;28;43mopen\u001b[39;49m\u001b[43m(\u001b[49m\u001b[38;5;124;43m\"\u001b[39;49m\u001b[38;5;124;43m/path/to/mars.jpg\u001b[39;49m\u001b[38;5;124;43m\"\u001b[39;49m\u001b[43m)\u001b[49m\n",
      "File \u001b[1;32md:\\Programmation\\PYTHON\\hello-world\\env\\Lib\\site-packages\\IPython\\core\\interactiveshell.py:310\u001b[0m, in \u001b[0;36m_modified_open\u001b[1;34m(file, *args, **kwargs)\u001b[0m\n\u001b[0;32m    303\u001b[0m \u001b[38;5;28;01mif\u001b[39;00m file \u001b[38;5;129;01min\u001b[39;00m {\u001b[38;5;241m0\u001b[39m, \u001b[38;5;241m1\u001b[39m, \u001b[38;5;241m2\u001b[39m}:\n\u001b[0;32m    304\u001b[0m     \u001b[38;5;28;01mraise\u001b[39;00m \u001b[38;5;167;01mValueError\u001b[39;00m(\n\u001b[0;32m    305\u001b[0m         \u001b[38;5;124mf\u001b[39m\u001b[38;5;124m\"\u001b[39m\u001b[38;5;124mIPython won\u001b[39m\u001b[38;5;124m'\u001b[39m\u001b[38;5;124mt let you open fd=\u001b[39m\u001b[38;5;132;01m{\u001b[39;00mfile\u001b[38;5;132;01m}\u001b[39;00m\u001b[38;5;124m by default \u001b[39m\u001b[38;5;124m\"\u001b[39m\n\u001b[0;32m    306\u001b[0m         \u001b[38;5;124m\"\u001b[39m\u001b[38;5;124mas it is likely to crash IPython. If you know what you are doing, \u001b[39m\u001b[38;5;124m\"\u001b[39m\n\u001b[0;32m    307\u001b[0m         \u001b[38;5;124m\"\u001b[39m\u001b[38;5;124myou can use builtins\u001b[39m\u001b[38;5;124m'\u001b[39m\u001b[38;5;124m open.\u001b[39m\u001b[38;5;124m\"\u001b[39m\n\u001b[0;32m    308\u001b[0m     )\n\u001b[1;32m--> 310\u001b[0m \u001b[38;5;28;01mreturn\u001b[39;00m \u001b[43mio_open\u001b[49m\u001b[43m(\u001b[49m\u001b[43mfile\u001b[49m\u001b[43m,\u001b[49m\u001b[43m \u001b[49m\u001b[38;5;241;43m*\u001b[39;49m\u001b[43margs\u001b[49m\u001b[43m,\u001b[49m\u001b[43m \u001b[49m\u001b[38;5;241;43m*\u001b[39;49m\u001b[38;5;241;43m*\u001b[39;49m\u001b[43mkwargs\u001b[49m\u001b[43m)\u001b[49m\n",
      "\u001b[1;31mFileNotFoundError\u001b[0m: [Errno 2] No such file or directory: '/path/to/mars.jpg'"
     ]
    }
   ],
   "source": [
    "def main():\n",
    "    open(\"/path/to/mars.jpg\")\n",
    "\n",
    "if __name__ == '__main__':\n",
    "    main()"
   ]
  },
  {
   "cell_type": "markdown",
   "metadata": {},
   "source": [
    "La description de l'erreur diffère car nous l'avons intégré dans un `main` auquel nous faisons appel.\n",
    "\n",
    "L'exception renvoie donc une référence d'abord à la ligne 5 de lancement de `main`, puis à la ligne 2 de notre fonction. L'erreur est bien sûr toujours un FileNotFoundError.\n",
    "\n",
    "Les traçages des erreurs incluent presque toujours les informations suivantes :\n",
    "* Tous les chemins de fichiers impliqués, pour chaque appel à chaque fonction.\n",
    "* Numéros de ligne associés à chaque chemin de fichier.\n",
    "* Les noms des fonctions, méthodes ou classes impliquées dans la production d’une exception.\n",
    "* Nom de l'exception déclenchée.\n",
    "\n",
    "## Gérer les exceptions\n",
    "Les sorties d'erreurs peuvent être très volumineuses. Imaginez que vous programmiez un système de navigation de fusée, que penseraient les utilisateurs (astronautes, comosnotes etc...) d'un tel affichage ?\n",
    "\n",
    "Il sera plus utilie d'apporter à l'utilisateur un message clair et facilement compréhensible de l'erreur (surtout si sa vie en dépend).\n",
    "\n",
    "### Les `try` et `except` blocs\n",
    "Nous savons maintenant que le fait d'ouvrir un fichier que le programme ne trouve pas soulève un `FileNotFoundError`. Nous pouvons tester une commande (try) et gérer la survenance d'une erreur (except).\n",
    "\n",
    "Par exemple, faisons en sorte que le programme affiche \"**Fichier config.jsn introuvable!**\" si on tente de l'ouvrir et qu'il n'existe pas."
   ]
  },
  {
   "cell_type": "code",
   "execution_count": 4,
   "metadata": {},
   "outputs": [
    {
     "name": "stdout",
     "output_type": "stream",
     "text": [
      "Fichier config.jsn introuvable!\n"
     ]
    }
   ],
   "source": [
    "try:\n",
    "    open(\"config.jsn\")\n",
    "except FileNotFoundError:\n",
    "    print(\"Fichier config.jsn introuvable!\")"
   ]
  },
  {
   "cell_type": "markdown",
   "metadata": {},
   "source": [
    "Nous avons tester une commande (try) et forcer l'affichage d'un message prédéfini si une erreur FileNotFoundError était levée.\n",
    "\n",
    "Cela empêche un traçage complet (pas d'incation de nom de fichiers, de chemin ou de ligne de programme) et ne concerne que ce type d'exception mais c'est plus clair pour l'utilisateur.\n",
    "\n",
    "Et si un autre type d'erreur apparaissait ?\n",
    "\n",
    "*Pour l'exemple suivant il est nécessaire qu'un **dossier** nommé config.txt soit présent dans le dossier de ce notebook.*"
   ]
  },
  {
   "cell_type": "code",
   "execution_count": 3,
   "metadata": {},
   "outputs": [
    {
     "ename": "PermissionError",
     "evalue": "[Errno 13] Permission denied: 'config.txt'",
     "output_type": "error",
     "traceback": [
      "\u001b[1;31m---------------------------------------------------------------------------\u001b[0m",
      "\u001b[1;31mPermissionError\u001b[0m                           Traceback (most recent call last)",
      "Cell \u001b[1;32mIn[3], line 8\u001b[0m\n\u001b[0;32m      5\u001b[0m         \u001b[38;5;28mprint\u001b[39m(\u001b[38;5;124m\"\u001b[39m\u001b[38;5;124mFichier config.txt introuvable!\u001b[39m\u001b[38;5;124m\"\u001b[39m)\n\u001b[0;32m      7\u001b[0m \u001b[38;5;28;01mif\u001b[39;00m \u001b[38;5;18m__name__\u001b[39m \u001b[38;5;241m==\u001b[39m \u001b[38;5;124m'\u001b[39m\u001b[38;5;124m__main__\u001b[39m\u001b[38;5;124m'\u001b[39m:\n\u001b[1;32m----> 8\u001b[0m     \u001b[43mmain\u001b[49m\u001b[43m(\u001b[49m\u001b[43m)\u001b[49m\n",
      "Cell \u001b[1;32mIn[3], line 3\u001b[0m, in \u001b[0;36mmain\u001b[1;34m()\u001b[0m\n\u001b[0;32m      1\u001b[0m \u001b[38;5;28;01mdef\u001b[39;00m \u001b[38;5;21mmain\u001b[39m():\n\u001b[0;32m      2\u001b[0m     \u001b[38;5;28;01mtry\u001b[39;00m:\n\u001b[1;32m----> 3\u001b[0m         \u001b[38;5;28;43mopen\u001b[39;49m\u001b[43m(\u001b[49m\u001b[38;5;124;43m\"\u001b[39;49m\u001b[38;5;124;43mconfig.txt\u001b[39;49m\u001b[38;5;124;43m\"\u001b[39;49m\u001b[43m)\u001b[49m\n\u001b[0;32m      4\u001b[0m     \u001b[38;5;28;01mexcept\u001b[39;00m \u001b[38;5;167;01mFileNotFoundError\u001b[39;00m:\n\u001b[0;32m      5\u001b[0m         \u001b[38;5;28mprint\u001b[39m(\u001b[38;5;124m\"\u001b[39m\u001b[38;5;124mFichier config.txt introuvable!\u001b[39m\u001b[38;5;124m\"\u001b[39m)\n",
      "File \u001b[1;32md:\\Programmation\\PYTHON\\hello-world\\env\\Lib\\site-packages\\IPython\\core\\interactiveshell.py:310\u001b[0m, in \u001b[0;36m_modified_open\u001b[1;34m(file, *args, **kwargs)\u001b[0m\n\u001b[0;32m    303\u001b[0m \u001b[38;5;28;01mif\u001b[39;00m file \u001b[38;5;129;01min\u001b[39;00m {\u001b[38;5;241m0\u001b[39m, \u001b[38;5;241m1\u001b[39m, \u001b[38;5;241m2\u001b[39m}:\n\u001b[0;32m    304\u001b[0m     \u001b[38;5;28;01mraise\u001b[39;00m \u001b[38;5;167;01mValueError\u001b[39;00m(\n\u001b[0;32m    305\u001b[0m         \u001b[38;5;124mf\u001b[39m\u001b[38;5;124m\"\u001b[39m\u001b[38;5;124mIPython won\u001b[39m\u001b[38;5;124m'\u001b[39m\u001b[38;5;124mt let you open fd=\u001b[39m\u001b[38;5;132;01m{\u001b[39;00mfile\u001b[38;5;132;01m}\u001b[39;00m\u001b[38;5;124m by default \u001b[39m\u001b[38;5;124m\"\u001b[39m\n\u001b[0;32m    306\u001b[0m         \u001b[38;5;124m\"\u001b[39m\u001b[38;5;124mas it is likely to crash IPython. If you know what you are doing, \u001b[39m\u001b[38;5;124m\"\u001b[39m\n\u001b[0;32m    307\u001b[0m         \u001b[38;5;124m\"\u001b[39m\u001b[38;5;124myou can use builtins\u001b[39m\u001b[38;5;124m'\u001b[39m\u001b[38;5;124m open.\u001b[39m\u001b[38;5;124m\"\u001b[39m\n\u001b[0;32m    308\u001b[0m     )\n\u001b[1;32m--> 310\u001b[0m \u001b[38;5;28;01mreturn\u001b[39;00m \u001b[43mio_open\u001b[49m\u001b[43m(\u001b[49m\u001b[43mfile\u001b[49m\u001b[43m,\u001b[49m\u001b[43m \u001b[49m\u001b[38;5;241;43m*\u001b[39;49m\u001b[43margs\u001b[49m\u001b[43m,\u001b[49m\u001b[43m \u001b[49m\u001b[38;5;241;43m*\u001b[39;49m\u001b[38;5;241;43m*\u001b[39;49m\u001b[43mkwargs\u001b[49m\u001b[43m)\u001b[49m\n",
      "\u001b[1;31mPermissionError\u001b[0m: [Errno 13] Permission denied: 'config.txt'"
     ]
    }
   ],
   "source": [
    "def main():\n",
    "    try:\n",
    "        open(\"config.txt\")\n",
    "    except FileNotFoundError:\n",
    "        print(\"Fichier config.txt introuvable!\")\n",
    "\n",
    "if __name__ == '__main__':\n",
    "    main()"
   ]
  },
  {
   "cell_type": "markdown",
   "metadata": {},
   "source": [
    "Ici nous avons une `PermissionError` car config.txt n'est pas un fichier mais un dossier. Cette erreur n'est pas traitée par notre try/except bloc et par conséquent a été complètement tracé.\n",
    "\n",
    "Nous pourrions empêcher tout traçage en prenant dans l'except toutes les exceptions avec `except Exception:` mais nous ne saurions pas de quelle erreur il s'agit et ne pourrions donc la traiter correctement. Par contre il est possible de traiter plusieurs cas d'erreur différents.\n",
    "\n",
    "Nous allons écrire une version du programme qui prend en compte les `FileNotFoundError` **et** les `PermissionError`."
   ]
  },
  {
   "cell_type": "code",
   "execution_count": 5,
   "metadata": {},
   "outputs": [
    {
     "name": "stdout",
     "output_type": "stream",
     "text": [
      "Config.txt est un dossier, impossible de le lire!\n"
     ]
    }
   ],
   "source": [
    "try:\n",
    "    configuration = open(\"config.txt\")\n",
    "except FileNotFoundError:\n",
    "    print(\"Le fichier config.txt est introuvable!\")\n",
    "except PermissionError:\n",
    "    print(\"Config.txt est un dossier, impossible de le lire!\")"
   ]
  },
  {
   "cell_type": "markdown",
   "metadata": {},
   "source": [
    "Nous pouvons aussi gérer plusieurs exception du même type avec une réponse commune, par exemple les erreurs dûes à une surcharge de solliciation du disque provoquant des temps d'accès trop longs. Pour cela on utilise des virgules dans l'except (voir exemple suivant)."
   ]
  },
  {
   "cell_type": "code",
   "execution_count": null,
   "metadata": {},
   "outputs": [],
   "source": [
    "def main():\n",
    "    try:\n",
    "        configuration = open('config.txt')\n",
    "    except FileNotFoundError:\n",
    "        print(\"Couldn't find the config.txt file!\")\n",
    "    except IsADirectoryError:\n",
    "        print(\"Found config.txt but it is a directory, couldn't read it\")\n",
    "    except (BlockingIOError, TimeoutError): # Prend en charge les erreur d'entrée/sortie et de délai trop long\n",
    "        print(\"Filesystem under heavy load, can't complete reading configuration file\")"
   ]
  },
  {
   "cell_type": "markdown",
   "metadata": {},
   "source": [
    "Enfin, il peut être utile de capturer le numéro d'erreur dans l'exception avec la commande `as`. Par exemple les erreurs `FileNotFoundError` et `PermissionError` ont pour parent `OSError` avec respectivement les numéros d'erreur 2 et 13.\n",
    "\n",
    "Nous pouvons donc élaborer le code suivant :"
   ]
  },
  {
   "cell_type": "code",
   "execution_count": 2,
   "metadata": {},
   "outputs": [
    {
     "name": "stdout",
     "output_type": "stream",
     "text": [
      "Found config.txt but couldn't read it\n"
     ]
    }
   ],
   "source": [
    "try:\n",
    "    open(\"config.txt\")\n",
    "except OSError as err:\n",
    "     if err.errno == 2:\n",
    "         print(\"Couldn't find the config.txt file!\")\n",
    "     elif err.errno == 13:\n",
    "        print(\"Found config.txt but couldn't read it\")"
   ]
  }
 ],
 "metadata": {
  "kernelspec": {
   "display_name": "env",
   "language": "python",
   "name": "python3"
  },
  "language_info": {
   "codemirror_mode": {
    "name": "ipython",
    "version": 3
   },
   "file_extension": ".py",
   "mimetype": "text/x-python",
   "name": "python",
   "nbconvert_exporter": "python",
   "pygments_lexer": "ipython3",
   "version": "3.12.0"
  }
 },
 "nbformat": 4,
 "nbformat_minor": 2
}
